Workbook

Sheet PRISMA
A1: PRISMA 2020 flow with protocol amendment (eligibility criteria IC5-IC10 added 19-20 October 2026)
A2: Counts below are formulas over Eligibility_core; identification and screening counts come from 2026_10_19_Screening_FullText_Retrieval.xlsx (Summary).
A4: IDENTIFICATION
A5: Records identified from 7 databases (Scopus, WoS, PubMed, IEEE Xplore, ACM DL, ERIC, ACL Anthology) | B5: 20130
A6: Duplicate records removed (title + first author) | B6: 7526
A7: SCREENING
A8: Records screened (title/abstract) | B8: 12604
A9: Records excluded | B9: 9718 | C9: rules 1,980; reading 7,738
A10: Reports sought for retrieval | B10: 2886 | C10: core 1,832; adjacent 1,054
A11: Reports not retrieved | B11: 319
A12: Reports assessed for eligibility (full text) | B12: 2567
A13: ELIGIBILITY (amended criteria)
A14: Excluded IC5: adjacent, not a core counselling dialogue system | B14: =B12-B15 -> 925 | C14: adjacent tier retained for context only
A15: Core CDS reports | B15: =COUNTA(Eligibility_core!A:A)-1 -> 1642
A16: Excluded IC6: no own or purpose-built system | B16: =COUNTIF(Eligibility_core!J:J,"N6") -> 198
A17: Excluded IC7: not evaluated with human end users | B17: =COUNTIF(Eligibility_core!J:J,"N7") -> 801
A18: Excluded IC8: no explicit counselling/helping approach | B18: =COUNTIF(Eligibility_core!J:J,"N8") -> 306
A19: Excluded: duplicate records | B19: =COUNTIF(Eligibility_core!J:J,"DUP*") -> 2
A20: Eligible CDS evaluations = Level-1 mapping set (reports) | B20: =COUNTIF(Eligibility_core!L:L,"Yes") -> 335 | C20: used for RQ1 trends and evaluation-approach mapping
A21: Excluded IC9: no intervention-outcome evaluation | B21: =COUNTIF(Eligibility_core!J:J,"N9") -> 142 | C21: kept in Level-1 map
A22: Excluded IC10: outcome evaluation without comparator/control | B22: =COUNTIF(Eligibility_core!J:J,"N10") -> 76 | C22: kept in Level-1 map
A23: INCLUDED
A24: Studies included in Level-2 synthesis | B24: =COUNTIF(Eligibility_core!J:J,"I") -> 115 | C24: RQ2-RQ4
A25: Reports of included studies (incl. linked secondary reports) | B25: =B24+COUNTIF(Eligibility_core!J:J,"LINK*") -> 117
A27: Protocol amendment: eligibility criteria
A28: IC5 Core CDS: a dialogue system whose primary purpose is to help a user explore a personal problem, regulate emotions, understand options or decide on a course of action, informed by counselling or helping practice.
A29: IC6 The study builds, adapts or evaluates a specific, purpose-built CDS (excludes probing off-the-shelf general chatbots, surveys, app-review or social-media analyses, frameworks without a system).
A30: IC7 The system was used by real human end users (excludes offline metrics, simulated users and expert rating of transcripts only).
A31: IC8 The dialogue design explicitly draws on a named counselling or helping approach (e.g., CBT, MI, ACT, DBT, PST, BA, SFBT, person-centred/helping skills, positive psychology, mindfulness, self-compassion, coaching, PFA, supportive-communication theory); generic "empathy" alone does not qualify.
A32: IC9 Intervention-outcome evaluation: participants used the CDS as an intervention and psychological, behavioural or well-being outcomes were measured.
A33: IC10 The outcome evaluation includes a comparator or control (randomised or non-randomised; between- or within-subjects).
A34: Rationale: the 2,567 retrieved reports were too many for in-depth synthesis; IC5-IC8 define the Level-1 mapping set and IC9-IC10 the Level-2 synthesis set. Single screener (AI-assisted); a second screener should code a random 20% in Eligibility_core column N to compute agreement/kappa.

Sheet Eligibility_core
A1: Unique ID | B1: Title | C1: First author | D1: Year | E1: Period | F1: Document type | G1: Source | H1: DOI | I1: PDF file | J1: Eligibility code | K1: Eligibility decision | L1: Level-1 map (IC5-IC8 eligible) | M1: Level-2 synthesis | N1: Second-screener code (to fill) | O1: Agreement
A2: U00006 | B2: Effects of AI-based chatbot coaching on goal attainment, self-efficacy, and stress: A longitudinal randomized experiment | C2: Ohlms | D2: 2027 | E2: 2023-2026 | F2: Journal article | G2: COMPUTERS IN HUMAN BEHAVIOR | H2: 10.1016/j.chb.2026.109184 | I2: U00006_Ohlms_2027.pdf | J2: I | K2: Included (Level-2 synthesis) | L2: Yes | M2: Yes | O2: =IF(N2="","",IF(N2=J2,1,0))
A3: U00025 | B3: "I Will Be Right Here Whenever You Need Me": Designing AI-Mediated Collaborative Support for Adolescent Mental Health in Border Regions | C3: Wei Gong | D3: 2026 | E3: 2023-2026 | F3: Conference paper | G3: Proceedings of the 2026 Companion of the Computer-Supported Cooperative Work and Social Computing | H3: 10.1145/3785651.3836636 | I3: U00025_Gong_2026.pdf | J3: N7 | K3: Excluded IC7: not evaluated with human end users | L3: No | M3: No | O3: =IF(N3="","",IF(N3=J3,1,0))
A4: U00027 | B4: "Is This Really a Human Peer Supporter?": Misalignments Between Peer Supporters and Experts in LLM-Supported Interactions | C4: Sim | D4: 2026 | E4: 2023-2026 | F4: Conference paper | G4: Proceedings of the ACM on Human-Computer Interaction | H4: 10.1145/3816956 | I4: U00027_Sim_2026.pdf | J4: N6 | K4: Excluded IC6: no own or purpose-built dialogue system | L4: No | M4: No | O4: =IF(N4="","",IF(N4=J4,1,0))
A5: U00028 | B5: "Like Having Family Nearby": An LLM-Powered Family-Resembling Avatar for offering Psychological Support and Training Guidance during Stroke Rehabilitation | C5: Xiong | D5: 2026 | E5: 2023-2026 | F5: Conference paper | G5: Conference on Human Factors in Computing Systems - Proceedings | H5: 10.1145/3772363.3798321 | I5: U00028_Xiong_2026.pdf | J5: N8 | K5: Excluded IC8: no explicit counselling/helping approach | L5: No | M5: No | O5: =IF(N5="","",IF(N5=J5,1,0))
A6: U00030 | B6: "This Isn&#x2019;t Living the Dream; I Want Out": Probing Generative AI for Aviation Mental Health Support Through an Exploratory Design Experiment | C6: Ranjitha Naruganahalli Rangaswamy | D6: 2026 | E6: 2023-2026 | F6: Conference paper | G6: Proceedings of the 2026 Companion of the Computer-Supported Cooperative Work and Social Computing | H6: 10.1145/3785651.3831532 | I6: U00030_Rangaswamy_2026.pdf | J6: N6 | K6: Excluded IC6: no own or purpose-built dialogue system | L6: No | M6: No | O6: =IF(N6="","",IF(N6=J6,1,0))
A7: U00032 | B7: "What Can I Control?": Designing an Attribution Reframing Chatbot for Early-Career Employees' Workplace Stress Management | C7: Lee | D7: 2026 | E7: 2023-2026 | F7: Conference paper | G7: Conference on Human Factors in Computing Systems - Proceedings | H7: 10.1145/3772363.3798873 | I7: U00032_Lee_2026.pdf | J7: N9 | K7: Excluded IC9: no intervention-outcome evaluation (Level-1 map only) | L7: Yes | M7: No | O7: =IF(N7="","",IF(N7=J7,1,0))
A8: U00035 | B8: "words are not enough": Examining Emotional Support by Conversational AI for Caregivers | C8: Vafafar | D8: 2026 | E8: 2023-2026 | F8: Conference paper | G8: Conference on Human Factors in Computing Systems - Proceedings | H8: 10.1145/3772318.3790647 | I8: U00035_Vafafar_2026.pdf | J8: N6 | K8: Excluded IC6: no own or purpose-built dialogue system | L8: No | M8: No | O8: =IF(N8="","",IF(N8=J8,1,0))
A9: U00037 | B9: ''It Hasn&#x2019;t Lived in Our Society&#x201d;: Investigating Cultural Sensitivity in LLM Chatbots for Emotional Support | C9: Sarah Aldaweesh | D9: 2026 | E9: 2023-2026 | F9: Conference paper | G9: Proceedings of the 2026 CHI Conference on Human Factors in Computing Systems | H9: 10.1145/3772318.3791060 | I9: U00037_Aldaweesh_2026.pdf | J9: N8 | K9: Excluded IC8: no explicit counselling/helping approach | L9: No | M9: No | O9: =IF(N9="","",IF(N9=J9,1,0))
A10: U00038 | B10: ''It Hasn't Lived in Our Society": Investigating Cultural Sensitivity in LLM Chatbots for Emotional Support | C10: Aldaweesh | D10: 2026 | E10: 2023-2026 | F10: Conference paper | G10: Conference on Human Factors in Computing Systems - Proceedings | H10: 10.1145/3772318.3791060 | I10: U00038_Aldaweesh_2026.pdf | J10: N8 | K10: Excluded IC8: no explicit counselling/helping approach | L10: No | M10: No | O10: =IF(N10="","",IF(N10=J10,1,0))
A11: U00056 | B11: A C-SSRS-Based Risk-Aware Evaluation Framework for Self-Harm Safety in LLMs | C11: Zhang | D11: 2026 | E11: 2023-2026 | F11: Conference paper | G11: Proceedings - 2026 IEEE International Conference on Artificial Intelligence Testing, AITest 2026 | H11: 10.1109/aitest70988.2026.00035 | I11: U00056_Zhang_2026.pdf | J11: N6 | K11: Excluded IC6: no own or purpose-built dialogue system | L11: No | M11: No | O11: =IF(N11="","",IF(N11=J11,1,0))
A12: U00061 | B12: A Chatbot for the Management of Bipolar Disorder: Using Retrieval-Augmented Generation With an Open-Weight Large Language Model to Answer Clinical Questions Based on the CANMAT and ISBD 2018 Guidelines for Bipolar Disorder | C12: Mali | D12: 2026 | E12: 2023-2026 | F12: Journal article | G12: CANADIAN JOURNAL OF PSYCHIATRY-REVUE CANADIENNE DE PSYCHIATRIE | H12: 10.1177/07067437261457232 | I12: U00061_Mali_2026.pdf | J12: N7 | K12: Excluded IC7: not evaluated with human end users | L12: No | M12: No | O12: =IF(N12="","",IF(N12=J12,1,0))
A13: U00062 | B13: A Chatbot for the Management of Bipolar Disorder: Using Retrieval-Augmented Generation With an Open-Weight Large Language Model to Answer Clinical Questions Based on the CANMAT and ISBD 2018 Guidelines for Bipolar Disorder: Un dialogueur pour la prise en charge du trouble bipolaire : utiliser la génération augmentée par récupération avec un grand modèle de langage (GML) à poids ouverts pour répondre aux questions cliniques fondées sur les lignes directrices de 2018 de CANMAT et de l'ISBD relatives au trouble bipolaire | C13: Mali | D13: 2026 | E13: 2023-2026 | F13: Journal article | G13: Canadian Journal of Psychiatry | H13: 10.1177/07067437261457232 | I13: U00062_Mali_2026.pdf | J13: N7 | K13: Excluded IC7: not evaluated with human end users | L13: No | M13: No | O13: =IF(N13="","",IF(N13=J13,1,0))
... A608: U05554 | B608: Attitudes towards AI counseling: the existence of perceptual fear in affecting perceived chatbot support quality | C608: Keung | D608: 2025 | E608: 2023-2026 | F608: Journal article | G608: Frontiers in Psychology | H608: 10.3389/fpsyg.2025.1538387 | I608: U05554_Keung_2025.pdf | J608: N8 | K608: Excluded IC8: no explicit counselling/helping approach | L608: No | M608: No | O608: =IF(N608="","",IF(N608=J608,1,0))
A609: U05585 | B609: Balancing Knowledge Delivery and Emotional Comfort in Healthcare Conversational Systems | C609: Tsai | D609: 2025 | E609: 2023-2026 | F609: Conference paper | G609: Proceedings of the 15th International Workshop on Spoken Dialogue Systems Technology | I609: U05585_Tsai_2025.pdf | J609: N7 | K609: Excluded IC7: not evaluated with human end users | L609: No | M609: No | O609: =IF(N609="","",IF(N609=J609,1,0))
A610: U05600 | B610: Behavior Emotion Therapy System and You: Co-Design and Evaluation of a Mental Health Chatbot and Digital Human for Mild to Moderate Anxiety in Healthy Participants | C610: Thunström | D610: 2025 | E610: 2023-2026 | F610: Journal article | G610: JMIR Formative Research | H610: 10.2196/66163 | I610: U05600_Thunstrom_2025.pdf | J610: N9 | K610: Excluded IC9: no intervention-outcome evaluation (Level-1 map only) | L610: Yes | M610: No | O610: =IF(N610="","",IF(N610=J610,1,0))
A611: U05606 | B611: Benchmarking AI in Mental Health: A Critical Examination of LLMs Across Key Performance and Ethical Metrics | C611: Yuan | D611: 2025 | E611: 2023-2026 | F611: Conference paper | G611: Lecture Notes in Computer Science (including subseries Lecture Notes in Artificial Intelligence and Lecture Notes in Bioinformatics) | H611: 10.1007/978-3-031-78104-9_24 | I611: U05606_Yuan_2025.pdf | J611: N7 | K611: Excluded IC7: not evaluated with human end users | L611: No | M611: No | O611: =IF(N611="","",IF(N611=J611,1,0))
A612: U05611 | B612: BetterMood: A human-like AI counseling service for adolescents and young adults | C612: Kim | D612: 2025 | E612: 2023-2026 | F612: Journal article | G612: Digital Health | H612: 10.1177/20552076251392294 | I612: U05611_Kim_2025.pdf | J612: N8 | K612: Excluded IC8: no explicit counselling/helping approach | L612: No | M612: No | O612: =IF(N612="","",IF(N612=J612,1,0))
A613: U05624 | B613: Beyond the Dialogue: Multi-chatbot Group Motivational Interviewing for Premenstrual Syndrome (PMS) Management | C613: Geng | D613: 2025 | E613: 2023-2026 | F613: Conference paper | G613: Conference on Human Factors in Computing Systems - Proceedings | H613: 10.1145/3706598.3713918 | I613: U05624_Geng_2025.pdf | J613: I | K613: Included (Level-2 synthesis) | L613: Yes | M613: Yes | O613: =IF(N613="","",IF(N613=J613,1,0))
A614: U05629 | B614: Beyond Words: Gaze-Enhanced LLM-based Dialogue System for Therapeutic Purposes | C614: Gabor-Siatkowska | D614: 2025 | E614: 2023-2026 | F614: Conference paper | G614: International Conference on Systems, Signals, and Image Processing | H614: 10.1109/iwssip66997.2025.11151860 | I614: U05629_Gabor-Siatkowska_2025.pdf | J614: N7 | K614: Excluded IC7: not evaluated with human end users | L614: No | M614: No | O614: =IF(N614="","",IF(N614=J614,1,0))
A615: U05643 | B615: Breaking Language Barriers in Mental Health: A Multilingual Chatbot for Global Support | C615: Benita | D615: 2025 | E615: 2023-2026 | F615: Conference paper | G615: International Conference on Computational Robotics, Testing and Engineering Evaluation, ICCRTEE 2025 | H615: 10.1109/iccrtee64519.2025.11052936 | I615: U05643_Benita_2025.pdf | J615: N7 | K615: Excluded IC7: not evaluated with human end users | L615: No | M615: No | O615: =IF(N615="","",IF(N615=J615,1,0))
A616: U05653 | B616: Bridging Gender Disparities in Mental Health: A Bilingual Large Language Model for Multilingual Therapeutic Chatbots | C616: Elboardy | D616: 2025 | E616: 2023-2026 | F616: Conference paper | G616: 22nd International Learning and Technology Conference: Human-Machine Dynamics Fueling a Sustainable Future, L and T 2025 | H616: 10.1109/lt64002.2025.10941308 | I616: U05653_Elboardy_2025.pdf | J616: N7 | K616: Excluded IC7: not evaluated with human end users | L616: No | M616: No | O616: =IF(N616="","",IF(N616=J616,1,0))
A617: U05663 | B617: Building a Digital Psychologist: An AI-Based Approach to Mental Health Support Using NLP and Therapeutic Models | C617: Sumitha | D617: 2025 | E617: 2023-2026 | F617: Conference paper | G617: 2nd International Conference on Research Methodologies in Knowledge Management, Artificial Intelligence and Telecommunication Engineering, RMKMATE 2025 | H617: 10.1109/rmkmate64874.2025.11042414 | I617: U05663_Sumitha_2025.pdf | J617: N7 | K617: Excluded IC7: not evaluated with human end users | L617: No | M617: No | O617: =IF(N617="","",IF(N617=J617,1,0))
A618: U05664 | B618: Building a Digital Psychologist: An AI-Based Approach to Mental Health Support Using NLP And Therapeutic Models | C618: S. T | D618: 2025 | E618: 2023-2026 | F618: Conference paper | G618: 2025 2nd International Conference on Research Methodologies in Knowledge Management, Artificial Intelligence and Telecommunication Engineering (RMKMATE) | H618: 10.1109/rmkmate64874.2025.11042414 | I618: U05664_T_2025.pdf | J618: N7 | K618: Excluded IC7: not evaluated with human end users | L618: No | M618: No | O618: =IF(N618="","",IF(N618=J618,1,0))
A619: U05667 | B619: Building and Beta-Testing Be Well Buddy Chatbot, a Secure, Credible and Trustworthy AI Chatbot That Will Not Misinform, Hallucinate or Stigmatize Substance Use Disorder: Development and Usability Study | C619: Salyers AJ | D619: 2025 | E619: 2023-2026 | F619: Journal article | G619: JMIR Hum Factors | H619: 10.2196/69144 | I619: U05667_Salyers-AJ_2025.pdf | J619: N8 | K619: Excluded IC8: no explicit counselling/helping approach | L619: No | M619: No | O619: =IF(N619="","",IF(N619=J619,1,0))
A620: U05669 | B620: CACKS: Context-Adaptive Commonsense Knowledge Selection for Empathetic Dialogue Generation | C620: Y. Wang | D620: 2025 | E620: 2023-2026 | F620: Conference paper | G620: 2025 44th Chinese Control Conference (CCC) | H620: 10.23919/ccc64809.2025.11178883 | I620: U05938_Tripathi_2025.pdf | J620: N7 | K620: Excluded IC7: not evaluated with human end users | L620: No | M620: No | O620: =IF(N620="","",IF(N620=J620,1,0))
A621: U05672 | B621: Calm Companion - An Enhanced Chatbot For Mental Health Support | C621: Verma | D621: 2025 | E621: 2023-2026 | F621: Conference paper | G621: Proceedings - 2025 5th International Conference on Expert Clouds and Applications, ICOECA 2025 | H621: 10.1109/icoeca66273.2025.00046 | I621: U05672_Verma_2025.pdf | J621: N7 | K621: Excluded IC7: not evaluated with human end users | L621: No | M621: No | O621: =IF(N621="","",IF(N621=J621,1,0))
... A749: U06391 | B749: Enhancing Emotional Support Conversation with Cognitive Chain-of-Thought Reasoning | C749: Cao | D749: 2025 | E749: 2023-2026 | F749: Conference paper | G749: Lecture Notes in Computer Science (including subseries Lecture Notes in Artificial Intelligence and Lecture Notes in Bioinformatics) | H749: 10.1007/978-981-97-9431-7_14 | I749: U06391_Cao_2025.pdf | J749: N7 | K749: Excluded IC7: not evaluated with human end users | L749: No | M749: No | O749: =IF(N749="","",IF(N749=J749,1,0))
A750: U06392 | B750: Enhancing Emotional Support Conversations: A Framework for Dynamic Knowledge Filtering and Persona Extraction | C750: Hao | D750: 2025 | E750: 2023-2026 | F750: Conference paper | G750: Proceedings - International Conference on Computational Linguistics, COLING | I750: U06392_Hao_2025.pdf | J750: N7 | K750: Excluded IC7: not evaluated with human end users | L750: No | M750: No | O750: =IF(N750="","",IF(N750=J750,1,0))
A751: U06406 | B751: Enhancing Mental Health Support Through Human-AI Collaboration: Toward Secure and Empathetic AI-Enabled Chatbots | C751: Almakinah | D751: 2025 | E751: 2023-2026 | F751: Conference paper | G751: Proceedings - 2025 IEEE Conference on Artificial Intelligence, CAI 2025 | H751: 10.1109/cai64502.2025.00038 | I751: U06406_Almakinah_2025.pdf | J751: N7 | K751: Excluded IC7: not evaluated with human end users | L751: No | M751: No | O751: =IF(N751="","",IF(N751=J751,1,0))
A752: U06407 | B752: Enhancing Mental Health Support: An LLM-Based Prompt Engineering Method | C752: Kaysar | D752: 2025 | E752: 2023-2026 | F752: Conference paper | G752: Lecture Notes in Networks and Systems | H752: 10.1007/978-981-97-9327-3_39 | I752: U06407_Kaysar_2025.pdf | J752: N8 | K752: Excluded IC8: no explicit counselling/helping approach | L752: No | M752: No | O752: =IF(N752="","",IF(N752=J752,1,0))
A753: U06409 | B753: Enhancing Mental Wellbeing Among College Students Using Autogen | C753: Reddy | D753: 2025 | E753: 2023-2026 | F753: Conference paper | G753: 2025 IEEE International Students' Conference on Electrical, Electronics and Computer Science, SCEECS 2025 | H753: 10.1109/sceecs64059.2025.10940967 | I753: U06409_Reddy_2025.pdf | J753: N7 | K753: Excluded IC7: not evaluated with human end users | L753: No | M753: No | O753: =IF(N753="","",IF(N753=J753,1,0))
A754: U06419 | B754: Enhancing physical activity through a relational artificial intelligence chatbot: A feasibility and usability study | C754: Oh | D754: 2025 | E754: 2023-2026 | F754: Journal article | G754: DIGITAL HEALTH | H754: 10.1177/20552076251324445 | I754: U06419_Oh_2025.pdf | J754: N8 | K754: Excluded IC8: no explicit counselling/helping approach | L754: No | M754: No | O754: =IF(N754="","",IF(N754=J754,1,0))
A755: U06442 | B755: ESC-Judge: A Framework for Comparing Emotional Support Conversational Agents | C755: Madani | D755: 2025 | E755: 2023-2026 | F755: Conference paper | G755: EMNLP 2025 - 2025 Conference on Empirical Methods in Natural Language Processing, Proceedings of the Conference | H755: 10.18653/v1/2025.emnlp-main.811 | I755: U06442_Madani_2025.pdf | J755: N7 | K755: Excluded IC7: not evaluated with human end users | L755: No | M755: No | O755: =IF(N755="","",IF(N755=J755,1,0))
A756: U06454 | B756: Ethically-Constrained Mental Health Chatbot for University Students: A Context-Aware NLP System using LLMs | C756: Syakurah | D756: 2025 | E756: 2023-2026 | F756: Conference paper | G756: EECSI 2025 - Proceedings 2025 12th International Conference on Electrical Engineering, Computer Science and Informatics | H756: 10.1109/eecsi67060.2025.11290231 | I756: U06454_Syakurah_2025.pdf | J756: N7 | K756: Excluded IC7: not evaluated with human end users | L756: No | M756: No | O756: =IF(N756="","",IF(N756=J756,1,0))
A757: U06466 | B757: Evaluating for Evidence of Sociodemographic Bias in Conversational AI for Mental Health Support | C757: Yeo | D757: 2025 | E757: 2023-2026 | F757: Journal article | G757: Cyberpsychology, Behavior, and Social Networking | H757: 10.1089/cyber.2024.0199 | I757: U06466_Yeo_2025.pdf | J757: N7 | K757: Excluded IC7: not evaluated with human end users | L757: No | M757: No | O757: =IF(N757="","",IF(N757=J757,1,0))
A758: U06468 | B758: Evaluating Generative AI Psychotherapy Chatbots Used by Youth: Cross-Sectional Study | C758: Sobowale | D758: 2025 | E758: 2023-2026 | F758: Journal article | G758: JMIR Mental Health | H758: 10.2196/79838 | I758: U06468_Sobowale_2025.pdf | J758: N6 | K758: Excluded IC6: no own or purpose-built dialogue system | L758: No | M758: No | O758: =IF(N758="","",IF(N758=J758,1,0))
A759: U06475 | B759: Evaluating Large Language Models for Enhancing Live Chat Therapy: A Comparative Study with Psychotherapists | C759: Deshpande | D759: 2025 | E759: 2023-2026 | F759: Conference paper | G759: Proceedings of the 26th Annual Meeting of the Special Interest Group on Discourse and Dialogue | H759: 10.18653/v1/2025.sigdial-1.59 | I759: U06475_Deshpande_2025.pdf | J759: N7 | K759: Excluded IC7: not evaluated with human end users | L759: No | M759: No | O759: =IF(N759="","",IF(N759=J759,1,0))
A760: U06491 | B760: Evaluating the Cultural Sensitivity of Large Language Models in Mental Health Support: A Framework Inspired by Ubuntu Values | C760: Forane | D760: 2025 | E760: 2023-2026 | F760: Conference paper | G760: Lecture Notes in Computer Science | H760: 10.1007/978-3-031-81821-9_18 | I760: U06491_Forane_2025.pdf | J760: N7 | K760: Excluded IC7: not evaluated with human end users | L760: No | M760: No | O760: =IF(N760="","",IF(N760=J760,1,0))
A761: U06492 | B761: EVALUATING THE EFFICACY OF CHATGPT IN PROVIDING EMOTIONAL SUPPORT: A COMPARATIVE STUDY OF AI AND HUMAN COUNSELING ON STUDENT MENTAL HEALTH OUTCOMES | C761: Atiyah | D761: 2025 | E761: 2023-2026 | F761: Conference paper | G761: Proceedings on Engineering Sciences | H761: 10.24874/pes07.04.008 | I761: 8 (2).pdf | J761: N6 | K761: Excluded IC6: no own or purpose-built dialogue system | L761: No | M761: No | O761: =IF(N761="","",IF(N761=J761,1,0))
...

Sheet Final_set_extraction
A1: Study ID | B1: Linked reports | C1: First author | D1: Year | E1: Title | F1: Venue | G1: Document type | H1: System | I1: Context / problem | J1: Population | K1: Counselling approach | L1: Dialogue technique | M1: Modality | N1: Design | O1: N | P1: Duration / dose | Q1: Comparator | R1: Outcome domains | S1: Main result vs comparator | T1: Notes / challenges | U1: DOI | V1: PDF file | W1: MMAT quality (to fill)
A2: U00006 | C2: Ohlms | D2: 2027 | E2: Effects of AI-based chatbot coaching on goal attainment, self-efficacy, and stress: A longitudinal randomized experiment | F2: COMPUTERS IN HUMAN BEHAVIOR | G2: Journal article | H2: AI coaching chatbot | I2: Academic goals and stress | J2: University students | K2: Coaching (solution-focused) | L2: LLM | M2: Text | N2: RCT | O2: 101 | P2: 4 sessions over a semester | Q2: Active (self-study) + waitlist | R2: Goal attainment; self-efficacy; stress | S2: Mixed | T2: Goal attainment improved; self-efficacy and stress effects inconsistent | U2: 10.1016/j.chb.2026.109184 | V2: U00006_Ohlms_2027.pdf
A3: U00135 | C3: Bryant | D3: 2026 | E3: A guided chatbot-based psychological intervention for psychologically distressed older adolescents and young adults: a randomised clinical trial in Jordan | F3: npj Digital Medicine | G3: Journal article | H3: STARS (WHO) | I3: Psychological distress | J3: Young adults, Jordan | K3: CBT / problem management (PM+) | L3: Rule-based (guided) | M3: Text | N3: RCT | O3: 344 | P3: 10 sessions + 5 support calls; 3-month follow-up | Q3: Enhanced usual care | R3: Anxiety; depression; distress; functioning; well-being | S3: Favours CDS | T3: Guided (e-helper) chatbot; LMIC humanitarian setting | U3: 10.1038/s41746-025-02142-8 | V3: U00135_Bryant_2026.pdf
A4: U00380 | C4: Huang | D4: 2026 | E4: Advanced robot interfaces are unnecessary for effective psychological health interventions | F4: Computers in Human Behavior Reports | G4: Journal article | H4: eiIBM delivered by text bot, audio bot and telepresence robot | I4: Depression | J4: Young adults | K4: Cognitive bias modification (CBT) | L4: Rule-based | M4: Text vs voice vs robot | N4: RCT | O4: 67 | P4: 6 sessions over 2 weeks | Q4: No intervention + modality comparison | R4: Depression; interpretation bias; user experience | S4: Favours CDS | T4: No difference between delivery modalities | U4: 10.1016/j.chbr.2026.100955 | V4: U00380_Huang_2026.pdf
A5: U00512 | C5: Huang | D5: 2026 | E5: AI Versus Human-Delivered Online Cognitive Behavioral Therapy for Anxiety Symptoms in Young Adults: A Randomized Controlled Trial | F5: Healthcare (Switzerland) | G5: Journal article | H5: AI-CBT chatbot | I5: Anxiety | J5: Young adults, China | K5: CBT | L5: LLM | M5: Text | N5: RCT | O5: 90 | P5: 4 weeks | Q5: Peer counsellor CBT + no intervention | R5: Anxiety; sleep; self-efficacy; perceived benefit | S5: No difference | T5: Within-group gains only; lower perceived benefit for AI | U5: 10.3390/healthcare14101325 | V5: U00512_Huang_2026.pdf
A6: U00726 | C6: Jackson | D6: 2026 | E6: App-based conversational agents for tinnitus distress and mental health: A randomised controlled trial | F6: Internet Interventions | G6: Journal article | H6: Tinnibot vs Woebot | I6: Tinnitus distress | J6: Adults with tinnitus | K6: iCBT + mindfulness | L6: Rule-based | M6: Text | N6: RCT | O6: 105 | P6: 8 weeks | Q6: Woebot + waitlist | R6: Tinnitus distress; anxiety; depression; insomnia | S6: Favours CDS | T6: Condition-specific bot outperformed generic bot on insomnia and tinnitus distress | U6: 10.1016/j.invent.2026.100944 | V6: U00726_Jackson_2026.pdf
A7: U00873 | C7: Schläpfer | D7: 2026 | E7: Association between working alliance and treatment outcomes in a mobile health intervention with a conversational agent (CanRelax) | F7: Internet Interventions | G7: Journal article | H7: CanRelax 2.0 | I7: Cancer-related distress | J7: Adults with cancer | K7: Mindfulness, relaxation, coaching (BCTs) | L7: Rule-based | M7: Text | N7: RCT (secondary analysis) | O7: 117 | P7: 10 weeks | Q7: (RCT arm) | R7: Working alliance; distress | S7: Mixed | T7: Alliance (task, goal) weakly associated with lower distress | U7: 10.1016/j.invent.2026.100929 | V7: U00873_Schlapfer_2026.pdf
A8: U01093 | C8: Yang | D8: 2026 | E8: Can AI be a good counselor? Comparing the effectiveness of AI and human career counseling | F8: Technology in Society | G8: Journal article | H8: Generative AI career counsellor | I8: Career decision-making | J8: University students, China | K8: Brief career counselling | L8: LLM | M8: Text | N8: Controlled trial | O8: 183 | P8: 3 weeks | Q8: Human career counselling | R8: Information; career decision self-efficacy; decision efficiency | S8: Mixed | T8: AI non-inferior for information; human better for self-efficacy and decision outcomes | U8: 10.1016/j.techsoc.2026.103301 | V8: U01093_Yang_2026.pdf
A9: U01136 | C9: Chen | D9: 2026 | E9: Caring with AI: The efficacy of a customised ChatGPT-delivered self-compassion intervention on college students' well-being and academic functioning | F9: Computers in Human Behavior Reports | G9: Journal article | H9: Your Self-Compassion Companion | I9: Well-being and academic functioning | J9: College students | K9: Self-compassion / CFT | L9: LLM | M9: Text | N9: RCT | O9: 220 | P9: 3 weekly 20-min sessions | Q9: Active control | R9: Self-compassion; self-criticism; self-esteem; academic engagement | S9: Favours CDS | T9: High completion (99%) | U9: 10.1016/j.chbr.2026.101267 | V9: U01136_Chen_2026.pdf
A10: U01326 | C10: Terblanche | D10: 2026 | E10: Comparing GROW, solution-focused and CBT coaching chatbots: a self-determination and transformative learning perspective | F10: Coaching | G10: Journal article | H10: GROW, SF and CBT coaching chatbots | I10: Personal development coaching | J10: Adults | K10: Coaching (GROW, solution-focused, CBT) | L10: LLM | M10: Text | N10: Randomised experiment (3 arms) | O10: 592 | P10: 2 sessions | Q10: Alternative coaching models | R10: Goal attainment; working alliance; technology adoption | S10: Favours CDS | T10: CBT-based bot outperformed GROW and SF bots | U10: 10.1080/17521882.2026.2625707 | V10: U01326_Terblanche_2026.pdf
A11: U01397 | C11: Sahab | D11: 2026 | E11: Conversational AI Agents for Mental Well-Being: A Pilot Randomized Controlled Trial with Afghan Women | F11: IEICE Transactions on Information and Systems | G11: Journal article | H11: Supportive Listener (GPT-4) | I11: Anxiety and depression | J11: Afghan women | K11: Person-centred, trauma-sensitive supportive listening | L11: LLM | M11: Text | N11: RCT | O11: 60 | P11: Several sessions | Q11: Standard GPT-4 + waitlist | R11: HADS; linguistic style matching; perceived empathy | S11: Favours CDS | T11: Instructions, not the base model, drove benefit | U11: 10.1587/transinf.2025dkp0015 | V11: U01397_Sahab_2026.pdf
A12: U01764 | C12: Kuta | D12: 2026 | E12: Effectiveness of a Fully Automated Mobile Therapeutic Versus a General Chatbot in Reducing Depression and Anxiety and Improving Well-Being: Feasibility Randomized Controlled Trial | F12: JMIR Mental Health | G12: Journal article | H12: Solution-focused AI therapy app | I12: Depression, anxiety, well-being | J12: Adults online | K12: Solution-focused brief therapy | L12: LLM | M12: Text | N12: RCT | O12: 147 | P12: 3 weeks (9 sessions) | Q12: ChatGPT + assessment-only | R12: PHQ-9; ODSIS; GAD-7; well-being | S12: Mixed | T12: Structured SF bot vs unstructured ChatGPT; low completion (39%) | U12: 10.2196/82642 | V12: U01764_Kuta_2026.pdf
A13: U01797 | B13: U00888 | C13: Shoshani | D13: 2026 | E13: Efficacy of a Conversational AI Agent for Psychiatric Symptoms and Digital Therapeutic Alliance A Randomized Clinical Trial | F13: JAMA Network Open | G13: Journal article | H13: AI conversational mental health platform | I13: Psychiatric symptoms | J13: University students with distress, Israel | K13: Integrative (CBT, ACT, DBT, positive psychology) | L13: LLM | M13: Text | N13: RCT | O13: 995 | P13: 12 weeks + 3-month follow-up | Q13: Group therapy + waitlist | R13: GAD-7; PHQ-9; PCL-5; WHO-5; life satisfaction; alliance | S13: Favours CDS | T13: Linked report U00888 (moderators: loneliness, attachment) | U13: 10.1001/jamanetworkopen.2026.6713 | V13: U01797_Shoshani_2026.pdf
A14: U01798 | C14: Li | D14: 2026 | E14: Efficacy of A Virtual Agent–Based Digital Intervention (Echo App V2.0) for Patients With Alcohol Use Disorder: Randomized Controlled Trial | F14: Journal of Medical Internet Research | G14: Journal article | H14: Echo App V2.0 | I14: Alcohol use disorder | J14: Inpatients, China | K14: CBT (+ MI) | L14: Rule-based (dialogue trees) | M14: ECA (digital human) | N14: RCT | O14: 93 | P14: 4 weeks (10 sessions); 3-month follow-up | Q14: TAU | R14: Craving; relapse; emotion; sleep; motivation | S14: Favours CDS | T14: Assessors blinded | U14: 10.2196/91065 | V14: U01798_Li_2026.pdf
A15: U01812 | C15: Kian | D15: 2026 | E15: Embodied Agent-Facilitated Virtual Support Groups for University Students | F15: IEEE Transactions on Affective Computing | G15: Journal article | H15: Robot-facilitated support group | I15: Anxiety and affect | J15: University students | K15: Facilitated support group (group therapy) | L15: LLM (Wizard-of-Oz framing) | M15: Robot | N15: Between/within experiment | O15: NR | P15: Single session | Q15: Perceived human-operated vs autonomous | R15: Anxiety; positive and negative affect; trust | S15: Favours CDS | T15: Pre-post reductions; no condition difference | U15: 10.1109/taffc.2026.3693987 | V15: U01812_Kian_2026.pdf
A16: U01815 | C16: Wang | D16: 2026 | E16: Embodied Miracle-Question Counseling in Virtual Reality | F16: Proceedings - 2026 IEEE Conference on Virtual Reality and 3D User Interfaces Abstracts and Workshops, VRW 2026 | G16: Conference paper | H16: VR Miracle-Question counselling | I16: Affect and goal reflection | J16: Adults | K16: SFBT (miracle question) | L16: LLM within scripted state machine | M16: VR | N16: Pre-post + between-subjects | O16: 20 | P16: Single session | Q16: Humanoid agent vs non-anthropomorphic metaphor | R16: Positive/negative affect; psychological safety | S16: Favours CDS | T16: LLM restricted to surface generation | U16: 10.1109/vrw70859.2026.00154 | V16: U01815_Wang_2026.pdf
A17: U01852 | C17: Yang | D17: 2026 | E17: Emotional support or problem-solving? A randomized controlled trial of function-specific AI Chatbots for digital stress in college students | F17: Applied Psychology: Health and Well-Being | G17: Journal article | H17: Emotional-support vs problem-solving chatbots | I17: Digital stress | J17: College students | K17: Supportive communication (emotional vs informational support) | L17: LLM | M17: Text | N17: RCT | O17: 99 | P17: 14 days | Q17: Waitlist | R17: Digital stress dimensions; anxiety; depression | S17: Mixed | T17: Function-specific effects; depression unchanged | U17: 10.1111/aphw.70208 | V17: U01852_Yang_2026.pdf
A18: U02130 | C18: Ye | D18: 2026 | E18: Exploring conflict-related behavioral intentions in AI and human role-playing interventions: evidence from behavioral experiments and linguistic analyses | F18: Cognitive Processing | G18: Journal article | H18: AI role-play conflict intervention | I18: Interpersonal conflict | J18: Adults | K18: Role-play (counselling technique) | L18: LLM | M18: Text | N18: Between-subjects experiments | O18: NR | P18: Single session | Q18: Human counsellor + no interaction | R18: Revenge intention; understanding; willingness to communicate | S18: Favours CDS | T18: Effects did not transfer to parallel scenarios | U18: 10.1007/s10339-026-01391-z | V18: U02130_Ye_2026.pdf
A19: U02507 | C19: Hennemann | D19: 2026 | E19: Generative AI versus human conversational agent for reducing procrastination: A randomized pilot trial | F19: Digital Health | G19: Journal article | H19: ChatGPT-4 CBT micro-intervention | I19: Procrastination | J19: University students | K19: CBT | L19: LLM | M19: Text | N19: Randomised pilot | O19: 62 | P19: 3 sessions; 6-month follow-up | Q19: Human conversational agent | R19: Procrastination; depression; anxiety; unwanted effects | S19: No difference | T19: 43% reported unwanted effects in both arms | U19: 10.1177/20552076261450336 | V19: U02507_Hennemann_2026.pdf
A20: U02593 | C20: Fang | D20: 2026 | E20: Harnessing large language models in virtual CBT for university students’ academic anxiety: a preliminary randomized trial | F20: Frontiers in Public Health | G20: Journal article | H20: LLM-VR-CBT | I20: Academic anxiety | J20: University students | K20: CBT | L20: LLM + RAG | M20: VR | N20: RCT | O20: 60 | P20: 4 weeks | Q20: Traditional CBT + minimal support | R20: Academic anxiety; heart rate | S20: Favours CDS | T20: Non-inferior to traditional CBT | U20: 10.3389/fpubh.2026.1874822 | V20: U02593_Fang_2026.pdf
A21: U02770 | C21: McFadyen | D21: 2026 | E21: Increasing engagement with cognitive-behavioral therapy (CBT) using generative AI: a randomized controlled trial (RCT) | F21: Communications Medicine | G21: Journal article | H21: GenAI-enabled CBT app | I21: Anxiety and depression | J21: US adults with symptoms | K21: CBT | L21: LLM | M21: Text | N21: RCT | O21: 540 | P21: 6 weeks | Q21: Digital CBT workbook | R21: Engagement; GAD-7; PHQ-9; adverse events | S21: Favours CDS | T21: Higher engagement than workbook | U21: 10.1038/s43856-025-01321-8 | V21: U02770_McFadyen_2026.pdf
A22: U02858 | C22: Matzenbacher | D22: 2026 | E22: Interactive Virtual Assistant for Health Promotion Among Older Adults With Type 2 Diabetes: The IVAM-ED Randomized Clinical Trial | F22: JAMA network open | G22: Journal article | H22: IVAM-ED (Alexa) | I22: Mental distress in diabetes | J22: Older adults with T2D, Brazil | K22: Behavioural intervention model | L22: Rule-based voice skill | M22: Smart speaker | N22: RCT | O22: NR | P22: 12 weeks | Q22: Usual care | R22: Mental distress; QoL; perceived stress; self-care; HbA1c | S22: Favours CDS | T22: Commercial smart speaker programmed for intervention | U22: 10.1001/jamanetworkopen.2025.53508 | V22: U02858_Matzenbacher_2026.pdf
A23: U03087 | C23: Zhang | D23: 2026 | E23: LLM-Assisted Counseling for Career Adaptability and Psychological Well-Being: A Longitudinal Study among Unemployed Adults in China | F23: Journal of Technology in Behavioral Science | G23: Journal article | H23: LLM-assisted counselling | I23: Unemployment distress and career adaptability | J23: Unemployed adults, China | K23: CBT + career adaptability | L23: LLM | M23: Text | N23: Randomised comparison | O23: 400 | P23: 12 bi-weekly sessions (6 months) | Q23: Supervised human online counselling | R23: GAD-7; career adaptability; acceptance | S23: Favours CDS | T23: Authors caution against generalising superiority | U23: 10.1007/s41347-026-00718-z | V23: U03087_Zhang_2026.pdf
A24: U03094 | C24: You | D24: 2026 | E24: LLM-based chatbots for academic stress counseling: comparing Socratic and Didactic styles in fostering stress reduction and therapeutic alliance | F24: Interactive Learning Environments | G24: Journal article | H24: Socratic vs didactic counselling chatbots | I24: Academic stress | J24: University students | K24: Socratic questioning (CBT) vs didactic | L24: LLM | M24: Text | N24: Within-subjects comparison | O24: 44 | P24: Repeated sessions | Q24: Counselling style | R24: Perceived stress; therapeutic alliance | S24: Favours CDS | T24: Didactic style outperformed Socratic style | U24: 10.1080/10494820.2026.2662461 | V24: U03094_You_2026.pdf
A25: U03118 | C25: Kian | D25: 2026 | E25: LLM-powered socially assistive robot-delivered cognitive behavioral therapy exercises: an exploratory study with university students | F25: Frontiers in Robotics and AI | G25: Journal article | H25: SAR-delivered CBT exercises | I25: Psychological distress and anxiety | J25: University students | K25: CBT | L25: LLM | M25: Robot vs text | N25: Randomised comparison (3 arms) | O25: 38 | P25: 15 days | Q25: Chatbot + worksheets | R25: Distress; session anxiety; adherence | S25: Mixed | T25: Robot and worksheet reduced distress; chatbot did not | U25: 10.3389/frobt.2026.1802622 | V25: U03118_Kian_2026.pdf
A26: U03301 | C26: Wong | D26: 2026 | E26: Motivational interviewing chatbot improves lifestyle in primary healthcare settings in a pragmatic randomised controlled trial | F26: npj Digital Medicine | G26: Journal article | H26: MI chatbot in primary care | I26: Lifestyle (NCD prevention) | J26: Adults 45-75 with/at risk of hypertension or diabetes | K26: Motivational interviewing | L26: Rule-based | M26: Text | N26: Pragmatic RCT | O26: 627 | P26: 12 weeks; 9-month follow-up | Q26: Usual care | R26: Physical activity; diet; committed action; blood pressure | S26: Favours CDS | T26: Dose-response; sustained at 9 months | U26: 10.1038/s41746-026-02728-w | V26: U03301_Wong_2026.pdf
A27: U03765 | C27: Meinert | D27: 2026 | E27: Real-World Testing of an Artificial Intelligence Conversational Agent as an Early Intervention and Support Tool in the Mental Health Referral Care Pathway: A Mixed-Methods Study | F27: International Journal of Social Psychiatry | G27: Journal article | H27: Wysa | I27: Depression and anxiety on waiting list | J27: NHS Talking Therapies patients | K27: CBT | L27: Hybrid (NLP + scripted) | M27: Text | N27: RCT | O27: 76 | P27: 12 weeks | Q27: Usual waiting | R27: PHQ-9; GAD-7; QoL; engagement | S27: No difference | T27: Under-powered; engagement limited by conversational errors | U27: 10.1177/00207640251415507 | V27: U03765_Meinert_2026.pdf
A28: U03769 | C28: Naumann | D28: 2026 | E28: Realistic human-like avatar embodiment diminishes outcomes in digital emotion regulation interventions | F28: Computers in Human Behavior Reports | G28: Journal article | H28: Embodied ER intervention avatars | I28: Emotion regulation | J28: Adults | K28: Emotion regulation (psychoeducation, gratitude, reappraisal) | L28: Rule-based | M28: ECA | N28: Between-subjects experiment (4 arms) | O28: 211 | P28: Single session | Q28: Audio-only control | R28: Emotions; satisfaction; user experience | S28: Mixed | T28: Realistic avatar lowered satisfaction (uncanny valley) | U28: 10.1016/j.chbr.2026.100952 | V28: U03769_Naumann_2026.pdf
A29: U04037 | C29: Shimojo | D29: 2026 | E29: Solution-Focused Embodied Conversational Agent for Older Adults: An Experimental Study on the Impact of Agent Impression | F29: Companion Proceedings of the 21st ACM/IEEE International Conference on Human-Robot Interaction, HRI Companion 2026 | G29: Conference paper | H29: Solution-focused ECA on robot | I29: Mental well-being in later life | J29: Older adults | K29: SFBT vs problem-focused approach | L29: Scripted | M29: Robot | N29: Randomised experiment | O29: 38 | P29: Single session | Q29: Problem-focused approach | R29: K10 distress; robot impressions | S29: No difference | T29: Perceived intelligence, not framework, predicted outcome | U29: 10.1145/3776734.3794479 | V29: U04037_Shimojo_2026.pdf
A30: U04222 | C30: Qiao | D30: 2026 | E30: The Anxiety Receipt: A Tangible RAG-LLM Interface for Emotional Externalization | F30: Lecture Notes in Computer Science | G30: Conference paper | H30: Anxiety Receipt | I30: Anxiety externalisation | J30: Young adults | K30: Expressive Therapies Continuum + CBT/ACT | L30: LLM + RAG | M30: Tangible interface | N30: Between-subjects experiment (EEG) | O30: 60 | P30: Single session | Q30: Screen-based interface | R30: EEG beta and frontal alpha asymmetry | S30: Favours CDS | T30: Physiological outcome only | U30: 10.1007/978-3-032-29839-3_31 | V30: U04222_Qiao_2026.pdf
A31: U04808 | C31: Zhang | D31: 2026 | E31: When Verse Listens Back: Classical Chinese Poetry as a Culturally Grounded Medium for Multimodal AI-Guided Emotional Support | F31: Conference on Human Factors in Computing Systems - Proceedings | G31: Conference paper | H31: Classical Chinese poetry support | I31: Negative affect | J31: University students | K31: Poetry therapy (RES model) | L31: LLM | M31: Multimodal (voice, image) | N31: Between-subjects experiment | O31: 50 | P31: Single session | Q31: Text-only version | R31: Affect; feeling understood; usability | S31: Favours CDS | T31: Culturally grounded design | U31: 10.1145/3772363.3798550 | V31: U04808_Zhang_2026.pdf
A32: U04844 | C32: Ajayi T | D32: 2026 | E32: Woebot for Postpartum Mood and Anxiety: Randomized Controlled Trial Evaluating Feasibility, Acceptability, and Preliminary Efficacy of a Mobile Cognitive Behavioral Therapy Intervention | F32: JMIR Pediatr Parent | G32: Journal article | H32: Woebot for Postpartum Mood and Anxiety | I32: Postpartum mood | J32: Postpartum individuals | K32: CBT | L32: Hybrid (NLP + scripted) | M32: Text | N32: RCT | O32: NR | P32: 8 weeks | Q32: Waitlist | R32: Feasibility; acceptability; satisfaction; mood | S32: Favours CDS | T32: Feasibility met across education levels | U32: 10.2196/74083 | V32: U04844_Ajayi-T_2026.pdf
A33: U05050 | C33: Gleason | D33: 2025 | E33: A Relational Agent Intervention for Adolescents Seeking Mental Health Treatment: Outcomes From a Randomized Controlled Trial Within a Children's Outpatient Hospital | F33: JAACAP Open | G33: Journal article | H33: Woebot (W-GenZD) | I33: Adolescent depression | J33: Adolescents in outpatient care | K33: CBT | L33: Hybrid (NLP + scripted) | M33: Text | N33: RCT (non-inferiority) | O33: 141 | P33: 4 weeks | Q33: Group telehealth CBT | R33: PHQ-8; working alliance; anxiety | S33: Favours CDS | T33: Non-inferior to clinician-led group CBT | U33: 10.1016/j.jaacop.2025.02.002 | V33: U05050_Gleason_2025.pdf
A34: U05247 | C34: Imkome | D34: 2025 | E34: Ai-Aun Chatbot: A Pilot Study on the Effectiveness of an Artificial Intelligence Intervention for Mental Health Among Thai Older Adults | F34: Nursing and Health Sciences | G34: Journal article | H34: Ai-Aun | I34: Mental health in later life | J34: Thai older adults | K34: Mixed (CBT, mindfulness, psychoeducation) | L34: Rule-based | M34: ECA (avatar) | N34: Randomised pilot | O34: 44 | P34: 15 days | Q34: No intervention | R34: Geriatric mental health | S34: Favours CDS | T34: High satisfaction | U34: 10.1111/nhs.70093 | V34: U05247_Imkome_2025.pdf
A35: U05369 | C35: Wang | D35: 2025 | E35: An Exploratory Study of Chatbot-Based Mindfulness for Mental Health Support | F35: Mindfulness | G35: Journal article | H35: Mindfulness and values chatbots | I35: Well-being and stress | J35: Post-secondary students | K35: Mindfulness (mindfulness-to-meaning) | L35: LLM | M35: Text | N35: Randomised experiments (2 studies) | O35: NR | P35: 1 and 4 weeks | Q35: Active check-in control | R35: Well-being; decentering; reappraisal | S35: Favours CDS | T35: Effect via decentering | U35: 10.1007/s12671-025-02685-7 | V35: U05369_Wang_2025.pdf
A36: U05455 | C36: Merrill | D36: 2025 | E36: Artificial intelligence chatbots as a source of virtual social support: Implications for loneliness and anxiety management | F36: Annals of the New York Academy of Sciences | G36: Journal article | H36: Person-centred social AI messages | I36: Loneliness and anxiety | J36: Adults (online panel) | K36: Supportive communication (person-centred messages) | L36: Scripted | M36: Text | N36: 2x2 between-subjects experiment | O36: NR | P36: Single session | Q36: Low person-centred messages | R36: Emotional validation; support quality | S36: Favours CDS | T36: Social presence moderated effects | U36: 10.1111/nyas.15400 | V36: U05455_Merrill_2025.pdf
A37: U05624 | C37: Geng | D37: 2025 | E37: Beyond the Dialogue: Multi-chatbot Group Motivational Interviewing for Premenstrual Syndrome (PMS) Management | F37: Conference on Human Factors in Computing Systems - Proceedings | G37: Conference paper | H37: Multi-chatbot group MI | I37: Premenstrual syndrome coping | J37: Women | K37: Motivational interviewing (group) | L37: LLM (multi-agent) | M37: Text | N37: Controlled study (3 conditions) | O37: 63 | P37: 2 menstrual cycles | Q37: No intervention + one-to-one chatbot | R37: Engagement; language convergence; coping | S37: Favours CDS | T37: Group format increased engagement and social learning | U37: 10.1145/3706598.3713918 | V37: U05624_Geng_2025.pdf
A38: U05742 | C38: Fujita J | D38: 2025 | E38: Challenges in Implementing a Mobile AI Chatbot Intervention for Depression Among Youth on Psychiatric Waiting Lists: Randomized Controlled Study Termination Report | F38: JMIRx Med | G38: Journal article | H38: emol | I38: Depression on psychiatric waiting lists | J38: Adolescents, Japan | K38: ACT | L38: Rule-based (commercial) | M38: Text | N38: RCT (terminated) | O38: 96 eligible | P38: 8 weekly sessions | Q38: Standard information | R38: PHQ-9 | S38: Feasibility only | T38: Terminated early; recruitment and implementation barriers | U38: 10.2196/70960 | V38: U05742_Fujita-J_2025.pdf
A39: U05862 | C39: Palmer | D39: 2025 | E39: Combining Artificial Intelligence and Human Support in Mental Health: Digital Intervention With Comparable Effectiveness to Human-Delivered Care | F39: Journal of Medical Internet Research | G39: Journal article | H39: Digital programme for anxiety (CA + human support) | I39: Generalised anxiety | J39: Adults, UK NHS | K39: CBT | L39: ML-driven CA with clinician oversight | M39: Text | N39: Non-randomised controlled (propensity-matched) | O39: 299 | P39: Up to 9 weeks; 1-month follow-up | Q39: Matched waitlist; face-to-face and typed CBT | R39: GAD-7; engagement; safety | S39: Favours CDS | T39: Non-inferior to human-delivered CBT | U39: 10.2196/69351 | V39: U05862_Palmer_2025.pdf
A40: U06042 | C40: Xu | D40: 2025 | E40: Depression intervention using AI chatbots with social cues: a randomized trial of effectiveness | F40: Journal of Affective Disorders | G40: Journal article | H40: High vs low social-cue chatbots | I40: Depression | J40: College students with PHQ-9 >= 9 | K40: CBT | L40: Scripted | M40: Text vs multimodal (voice, animation) | N40: RCT | O40: 84 | P40: 16 weeks | Q40: Text-only chatbot | R40: PHQ-9; GAD-7; PANAS; alliance; adherence | S40: Favours CDS | T40: Social cues improved symptoms and adherence | U40: 10.1016/j.jad.2025.119760 | V40: U06042_Xu_2025.pdf
...

Sheet Level1_map
A1: Unique ID | B1: Title | C1: Year | D1: Period | E1: Document type | F1: Context (keyword) | G1: Population (keyword) | H1: Counselling approach (keyword) | I1: Dialogue technique (keyword) | J1: Modality (keyword) | K1: Evaluation design (keyword) | L1: Eligibility code | M1: In Level-2 synthesis
A2: U00006 | B2: Effects of AI-based chatbot coaching on goal attainment, self-efficacy, and stress: A longitudinal randomized experiment | C2: 2027 | D2: 2023-2026 | E2: Journal article | F2: Stress | G2: Students | H2: Coaching | I2: LLM / generative | J2: Text | K2: Randomised controlled (RCT or randomised experiment) | L2: I | M2: Yes
A3: U00032 | B3: "What Can I Control?": Designing an Attribution Reframing Chatbot for Early-Career Employees' Workplace Stress Management | C3: 2026 | D3: 2023-2026 | E3: Conference paper | F3: Stress | G3: Workers | H3: CBT | I3: LLM / generative | J3: VR / AR | K3: Usability / acceptability / qualitative | L3: N9 | M3: No
A4: U00070 | B4: A cognitive layer architecture to support large-language model performance in psychotherapy interactions | C4: 2026 | D4: 2023-2026 | E4: Journal article | F4: Well-being/positive | G4: Patients/clinical | H4: CBT | I4: LLM / generative | J4: Text | K4: Real-world use / log analysis | L4: N9 | M4: No
A5: U00091 | B5: A conversational agent as a virtual therapist for patients diagnosed with schizophrenia: A preliminary study | C5: 2026 | D5: 2023-2026 | E5: Journal article | F5: Relationships/conflict | G5: Patients/clinical | H5: CBT | I5: NLU / ML (hybrid) | J5: VR / AR | K5: Single-arm pre-post outcome study | L5: N10 | M5: No
A6: U00092 | B6: A Conversational Agent for Motivational Interviewing with Summary Prediction | C6: 2026 | D6: 2023-2026 | E6: Conference paper | F6: General mental health | G6: General adults | H6: Motivational interviewing | I6: Hybrid (rule + generative) | J6: Voice | K6: Experiment on perceptions or design variants | L6: N9 | M6: No
A7: U00135 | B7: A guided chatbot-based psychological intervention for psychologically distressed older adolescents and young adults: a randomised clinical trial in Jordan | C7: 2026 | D7: 2023-2026 | E7: Journal article | F7: General mental health | G7: General adults | H7: CBT | I7: Rule-based / scripted | J7: Text | K7: Randomised controlled (RCT or randomised experiment) | L7: I | M7: Yes
A8: U00249 | B8: A Robot-Led Intervention for Emotion Regulation: from Expression to Reappraisal | C8: 2026 | D8: 2023-2026 | E8: Journal article | F8: Depression/anxiety | G8: Students | H8: CBT | I8: Hybrid (rule + generative) | J8: Robot | K8: Single-arm pre-post outcome study | L8: N10 | M8: No
A9: U00267 | B9: A Social Affective Robot for Emotion Regulation to Mitigate Procrastination in Adolescents | C9: 2026 | D9: 2023-2026 | E9: Conference paper | F9: Depression/anxiety | G9: Students | H9: Person-centred / helping skills | I9: Not reported | J9: Robot | K9: Experiment on perceptions or design variants | L9: N9 | M9: No
A10: U00270 | B10: A staged approach to the development of an embodied conversational agent to support wellbeing after injury | C10: 2026 | D10: 2023-2026 | E10: Journal article | F10: Well-being/positive | G10: Students | H10: Other named approach | I10: Not reported | J10: Embodied virtual agent | K10: Real-world use / log analysis | L10: N9 | M10: No
A11: U00300 | B11: A Therapeutic Conversational Agent (Solace) for Management of Chronic Pain: Acceptability and Usability Study | C11: 2026 | D11: 2023-2026 | E11: Journal article | F11: Depression/anxiety | G11: Patients/clinical | H11: CBT | I11: Hybrid (rule + generative) | J11: Text | K11: Single-arm pre-post outcome study | L11: N10 | M11: No
A12: U00367 | B12: Addressing Low Self Esteem in Pakistani University Students via an Embodied Conversational Agent | C12: 2026 | D12: 2023-2026 | E12: Conference paper | F12: General mental health | G12: Students | H12: CBT | I12: Rule-based / scripted | J12: Embodied virtual agent | K12: Single-arm pre-post outcome study | L12: N10 | M12: No
A13: U00380 | B13: Advanced robot interfaces are unnecessary for effective psychological health interventions | C13: 2026 | D13: 2023-2026 | E13: Journal article | F13: Depression/anxiety | G13: General adults | H13: CBT | I13: Rule-based / scripted | J13: Robot | K13: Randomised controlled (RCT or randomised experiment) | L13: I | M13: Yes
... A336: U12464 | B336: Can a virtual listener replace a human listener in active listening conversation? | C336: 2015 | D336: 2012-2016 | E336: Conference paper | F336: General mental health | G336: Older adults | H336: Person-centred / helping skills | I336: Not reported | J336: Embodied virtual agent | K336: Experiment on perceptions or design variants | L336: N9 | M336: No

Sheet Trends_RQ1
A1: Year | B1: Core retrieved (IC5) | C1: Eligible CDS evaluations (IC5-IC8, Level-1) | D1: Final synthesis (IC5-IC10, Level-2)
A2: 2012 | B2: =COUNTIF(Eligibility_core!D:D,A2) -> 5 | C2: =COUNTIFS(Eligibility_core!D:D,A2,Eligibility_core!L:L,"Yes") -> 0 | D2: =COUNTIFS(Eligibility_core!D:D,A2,Eligibility_core!M:M,"Yes") -> 0
A3: 2013 | B3: =COUNTIF(Eligibility_core!D:D,A3) -> 5 | C3: =COUNTIFS(Eligibility_core!D:D,A3,Eligibility_core!L:L,"Yes") -> 0 | D3: =COUNTIFS(Eligibility_core!D:D,A3,Eligibility_core!M:M,"Yes") -> 0
A4: 2014 | B4: =COUNTIF(Eligibility_core!D:D,A4) -> 2 | C4: =COUNTIFS(Eligibility_core!D:D,A4,Eligibility_core!L:L,"Yes") -> 0 | D4: =COUNTIFS(Eligibility_core!D:D,A4,Eligibility_core!M:M,"Yes") -> 0
A5: 2015 | B5: =COUNTIF(Eligibility_core!D:D,A5) -> 2 | C5: =COUNTIFS(Eligibility_core!D:D,A5,Eligibility_core!L:L,"Yes") -> 2 | D5: =COUNTIFS(Eligibility_core!D:D,A5,Eligibility_core!M:M,"Yes") -> 0
A6: 2016 | B6: =COUNTIF(Eligibility_core!D:D,A6) -> 5 | C6: =COUNTIFS(Eligibility_core!D:D,A6,Eligibility_core!L:L,"Yes") -> 4 | D6: =COUNTIFS(Eligibility_core!D:D,A6,Eligibility_core!M:M,"Yes") -> 2
A7: 2017 | B7: =COUNTIF(Eligibility_core!D:D,A7) -> 12 | C7: =COUNTIFS(Eligibility_core!D:D,A7,Eligibility_core!L:L,"Yes") -> 5 | D7: =COUNTIFS(Eligibility_core!D:D,A7,Eligibility_core!M:M,"Yes") -> 2
A8: 2018 | B8: =COUNTIF(Eligibility_core!D:D,A8) -> 21 | C8: =COUNTIFS(Eligibility_core!D:D,A8,Eligibility_core!L:L,"Yes") -> 5 | D8: =COUNTIFS(Eligibility_core!D:D,A8,Eligibility_core!M:M,"Yes") -> 2
A9: 2019 | B9: =COUNTIF(Eligibility_core!D:D,A9) -> 21 | C9: =COUNTIFS(Eligibility_core!D:D,A9,Eligibility_core!L:L,"Yes") -> 12 | D9: =COUNTIFS(Eligibility_core!D:D,A9,Eligibility_core!M:M,"Yes") -> 3
A10: 2020 | B10: =COUNTIF(Eligibility_core!D:D,A10) -> 43 | C10: =COUNTIFS(Eligibility_core!D:D,A10,Eligibility_core!L:L,"Yes") -> 14 | D10: =COUNTIFS(Eligibility_core!D:D,A10,Eligibility_core!M:M,"Yes") -> 6
A11: 2021 | B11: =COUNTIF(Eligibility_core!D:D,A11) -> 73 | C11: =COUNTIFS(Eligibility_core!D:D,A11,Eligibility_core!L:L,"Yes") -> 24 | D11: =COUNTIFS(Eligibility_core!D:D,A11,Eligibility_core!M:M,"Yes") -> 7
A12: 2022 | B12: =COUNTIF(Eligibility_core!D:D,A12) -> 74 | C12: =COUNTIFS(Eligibility_core!D:D,A12,Eligibility_core!L:L,"Yes") -> 30 | D12: =COUNTIFS(Eligibility_core!D:D,A12,Eligibility_core!M:M,"Yes") -> 9
A13: 2023 | B13: =COUNTIF(Eligibility_core!D:D,A13) -> 109 | C13: =COUNTIFS(Eligibility_core!D:D,A13,Eligibility_core!L:L,"Yes") -> 32 | D13: =COUNTIFS(Eligibility_core!D:D,A13,Eligibility_core!M:M,"Yes") -> 12
... A17: 2027 | B17: =COUNTIF(Eligibility_core!D:D,A17) -> 1 | C17: =COUNTIFS(Eligibility_core!D:D,A17,Eligibility_core!L:L,"Yes") -> 1 | D17: =COUNTIFS(Eligibility_core!D:D,A17,Eligibility_core!M:M,"Yes") -> 1
A18: Total | B18: =SUM(B2:B17) -> 1642 | C18: =SUM(C2:C17) -> 335 | D18: =SUM(D2:D17) -> 115
A20: Note: 2027 = early-access articles dated 2027 in the databases.

Sheet Map_summary
A1: Dimension | B1: Category | C1: Level-1 eligible (n) | D1: Level-1 % | E1: Level-2 final (n) | F1: Level-2 %
A2: Counselling approach | B2: CBT | C2: =COUNTIF(Level1_map!H:H,B2) -> 148 | D2: =C2/(COUNTA(Level1_map!A:A)-1) -> 0.44179104 | E2: =COUNTIFS(Level1_map!H:H,B2,Level1_map!M:M,"Yes") -> 70 | F2: =E2/COUNTIF(Level1_map!M:M,"Yes") -> 0.60869565
A3: Counselling approach | B3: Motivational interviewing | C3: =COUNTIF(Level1_map!H:H,B3) -> 37 | D3: =C3/(COUNTA(Level1_map!A:A)-1) -> 0.11044776 | E3: =COUNTIFS(Level1_map!H:H,B3,Level1_map!M:M,"Yes") -> 10 | F3: =E3/COUNTIF(Level1_map!M:M,"Yes") -> 0.086956522
A4: Counselling approach | B4: Other named approach | C4: =COUNTIF(Level1_map!H:H,B4) -> 26 | D4: =C4/(COUNTA(Level1_map!A:A)-1) -> 0.07761194 | E4: =COUNTIFS(Level1_map!H:H,B4,Level1_map!M:M,"Yes") -> 4 | F4: =E4/COUNTIF(Level1_map!M:M,"Yes") -> 0.034782609
A5: Counselling approach | B5: Positive psychology | C5: =COUNTIF(Level1_map!H:H,B5) -> 26 | D5: =C5/(COUNTA(Level1_map!A:A)-1) -> 0.07761194 | E5: =COUNTIFS(Level1_map!H:H,B5,Level1_map!M:M,"Yes") -> 7 | F5: =E5/COUNTIF(Level1_map!M:M,"Yes") -> 0.060869565
A6: Counselling approach | B6: Person-centred / helping skills | C6: =COUNTIF(Level1_map!H:H,B6) -> 24 | D6: =C6/(COUNTA(Level1_map!A:A)-1) -> 0.071641791 | E6: =COUNTIFS(Level1_map!H:H,B6,Level1_map!M:M,"Yes") -> 7 | F6: =E6/COUNTIF(Level1_map!M:M,"Yes") -> 0.060869565
A7: Counselling approach | B7: Mindfulness | C7: =COUNTIF(Level1_map!H:H,B7) -> 21 | D7: =C7/(COUNTA(Level1_map!A:A)-1) -> 0.062686567 | E7: =COUNTIFS(Level1_map!H:H,B7,Level1_map!M:M,"Yes") -> 4 | F7: =E7/COUNTIF(Level1_map!M:M,"Yes") -> 0.034782609
A8: Counselling approach | B8: Coaching | C8: =COUNTIF(Level1_map!H:H,B8) -> 17 | D8: =C8/(COUNTA(Level1_map!A:A)-1) -> 0.050746269 | E8: =COUNTIFS(Level1_map!H:H,B8,Level1_map!M:M,"Yes") -> 3 | F8: =E8/COUNTIF(Level1_map!M:M,"Yes") -> 0.026086957
A9: Counselling approach | B9: Exposure | C9: =COUNTIF(Level1_map!H:H,B9) -> 11 | D9: =C9/(COUNTA(Level1_map!A:A)-1) -> 0.032835821 | E9: =COUNTIFS(Level1_map!H:H,B9,Level1_map!M:M,"Yes") -> 1 | F9: =E9/COUNTIF(Level1_map!M:M,"Yes") -> 0.0086956522
A10: Counselling approach | B10: ACT | C10: =COUNTIF(Level1_map!H:H,B10) -> 5 | D10: =C10/(COUNTA(Level1_map!A:A)-1) -> 0.014925373 | E10: =COUNTIFS(Level1_map!H:H,B10,Level1_map!M:M,"Yes") -> 3 | F10: =E10/COUNTIF(Level1_map!M:M,"Yes") -> 0.026086957
A11: Counselling approach | B11: Behavioural activation | C11: =COUNTIF(Level1_map!H:H,B11) -> 5 | D11: =C11/(COUNTA(Level1_map!A:A)-1) -> 0.014925373 | E11: =COUNTIFS(Level1_map!H:H,B11,Level1_map!M:M,"Yes") -> 0 | F11: =E11/COUNTIF(Level1_map!M:M,"Yes") -> 0
A12: Counselling approach | B12: Psychoeducation | C12: =COUNTIF(Level1_map!H:H,B12) -> 5 | D12: =C12/(COUNTA(Level1_map!A:A)-1) -> 0.014925373 | E12: =COUNTIFS(Level1_map!H:H,B12,Level1_map!M:M,"Yes") -> 0 | F12: =E12/COUNTIF(Level1_map!M:M,"Yes") -> 0
